Workbook

Sheet Register
A1: TC-ID | B1: Description (Test Scenario) | C1: Pre-condition | D1: Test step | E1: Step condition to perform | F1: Data | G1: Priority | H1: Expected result | I1: Testing Result | K1: Date | L1: Who checked | M1: BUG ID | N1: Comment
I2: Chrome | J2: Microsoft Egde
A3: RE-001 | B3: Register successfully | C3: Stay at Register screen | D3: 1. Fill all required fields 2. Click Register button | E3: 1.1 Verify that user can register successfully with valid data | F3: First Name: abc Last Name: abc Email: h@gmail.com Password: 123456 Confirm Password: 123456 | G3: High | H3: Registration successful, System redirects to registration success page, User logged in automatically | I3: Passed | J3: Passed
A4: RE-002 | B4: Register with optional fields | C4: Stay at Register screen | D4: 1. Fill all required fields 2. Fill optional fields 3. Click Register | E4: 2.1 Verify that user can register with Gender field | F4: Gender: " "/Male/Female First Name: abc Last Name: abc Email: h@gmail.com Password: 123456 Confirm Password: 123456 | G4: Low | H4: Registration successful, System redirects to registration success page | I4: Passed | J4: Passed
A5: RE-003 | E5: 2.2 Verify that user can register with Company field | F5: First Name: abc Last Name: abc Email: h@gmail.com Company: " "/ "abc" Password: 123456 Confirm Password: 123456 | G5: Low | I5: Passed | J5: Passed
A6: RE-004 | E6: 2.3 Verify that user can register with Newsletter option selected | F6: First Name: abc Last Name: abc Email: h@gmail.com Newsletter: checked/unchecked Password: 123456 Confirm Password: 123456 | G6: Low | I6: Passed | J6: Passed
A7: RE-005 | B7: Register unsuccessful by First Name | C7: Stay at Register screen | D7: 1. Fill all required fields( except: First Name) 2. Input invalid First Name 3. Click Register | E7: 2.1 Verify that system displays error when First Name is empty | F7: First Name: " " Last Name: abc Email: h@gmail.com Password: 123456 Confirm Password: 123456 | G7: High | H7: Error message "First name is required" | I7: Passed | J7: Passed
A8: RE-006 | E8: 2.2 Verify that system displays error when First Name contains numbers | F8: First Name: 12345 Last Name: abc Email: h@gmail.com Password: 123456 Confirm Password: 123456 | G8: Medium | H8: Error message displayed | I8: Failed | J8: Failed
A9: RE-007 | E9: 2.3 Verify that system displays error when First Name contains special characters | F9: First Name: @#$% Last Name: abc Email: h@gmail.com Password: 123456 Confirm Password: 123456 | G9: Medium | I9: Failed | J9: Failed
A10: RE-008 | E10: 2.4 Verify that system displays error when First Name exceeds maximum length | F10: First Name: (long firstname) Last Name: abc Email: h@gmail.com Password: 123456 Confirm Password: 123456 | G10: Medium | I10: Failed | J10: Failed
A11: RE-009 | B11: Register unsuccessful by Last Name | C11: Stay at Register screen | D11: 1. Fill all required fields(except: Last Name) 2. Input invalid Last Name 3. Click Register | E11: 2.1 Verify that system displays error when Last Name is empty | F11: First Name: abc Last Name: " " Email: h@gmail.com Password: 123456 Confirm Password: 123456 | G11: High | H11: Error message "Last name is required" | I11: Passed | J11: Passed
A12: RE-010 | E12: 2.2 Verify that system displays error when Last Name contains numbers | F12: First Name: abc Last Name: 12345 Email: h@gmail.com Password: 123456 Confirm Password: 123456 | G12: Medium | H12: Error message displayed | I12: Failed | J12: Failed
A13: RE-011 | E13: 2.3 Verify that system displays error when Last Name contains special characters | F13: First Name: abc Last Name: @#$% Email: h@gmail.com Password: 123456 Confirm Password: 123456 | G13: Medium | I13: Failed | J13: Failed
A14: RE-012 | E14: 2.4 Verify that system displays error when Last Name exceeds maximum length | F14: First Name: abc Last Name: (long lastname) Email: h@gmail.com Password: 123456 Confirm Password: 123456 | G14: Medium | I14: Failed | J14: Failed
A15: RE-013 | B15: Register unsuccessful by Email | C15: Stay at Register screen | D15: 1. Fill all required fields(except: Email) 2. Input invalid Email 3. Click Register | E15: 2.1 Verify that system displays error when Email is empty | F15: First Name: abc Last Name: abc Email: " " Password: 123456 Confirm Password: 123456 | G15: High | H15: Error message "Email is required" | I15: Passed | J15: Passed
A16: RE-014 | E16: 2.2 Verify that system displays error when Email is missing '@' | F16: First Name: abc Last Name: abc Email: abcgmail.com Password: 123456 Confirm Password: 123456 | G16: High | H16: Error message displayed "Please enter a valid email address." | I16: Passed | J16: Passed
A17: RE-015 | E17: 2.3 Verify that system displays error when Email is missing domain | F17: First Name: abc Last Name: abc Email: abc@ Password: 123456 Confirm Password: 123456 | G17: High | I17: Passed | J17: Passed
A18: RE-016 | E18: 2.4 Verify that system displays error when Email contains spaces | F18: First Name: abc Last Name: abc Email: abc @gmail.com Password: 123456 Confirm Password: 123456 | G18: High | I18: Passed | J18: Passed
A19: RE-017 | E19: 2.5 Verify that system displays error when Email contains invalid special characters | F19: First Name: abc Last Name: abc Email: !#$%^^@gmail.com Password: 123456 Confirm Password: 123456 | G19: High | I19: Failed | J19: Failed
A20: RE-018 | E20: 2.6 Verify that system displays error when Email exceeds maximum length | F20: First Name: abc Last Name: abc Email: totalLength = 260 Password: 123456 Confirm Password: 123456 | G20: High | I20: Failed | J20: Failed
A21: RE-019 | E21: 2.7 Verify that system displays error when Email is already registered | F21: First Name: abc Last Name: abc Email: existing email Password: 123456 Confirm Password: 123456 | G21: High | H21: Error message "The specified email already exists" | I21: Passed | J21: Passed
A22: RE-020 | B22: Register unsuccessful by Password | C22: Stay at Register screen | D22: 1. Fill all required fields(except: Password) 2. Input invalid Password 3. Click Register | E22: 2.1 Verify that system displays error when Password is empty | F22: First Name: abc Last Name: abc Email: h@gmail.com Password: " " Confirm Password: " " | G22: High | H22: Error message displayed: "Password is required." | I22: Passed | J22: Passed
A23: RE-021 | E23: 2.2 Verify that system displays error when Password is shorter than minimum length | F23: First Name: abc Last Name: abc Email: h@gmail.com Password: 123 Confirm Password: 123 | G23: High | H23: Error message displayed: "must have at least 6 characters and not greater than 64 characters" | I23: Passed | J23: Passed
A24: RE-022 | E24: 2.3 Verify that system displays error when Password exceeds maximum length | F24: First Name: abc Last Name: abc Email: h@gmail.com Password: >64 char Confirm Password: >64 char | G24: Medium | I24: Passed | J24: Passed
A25: RE-023 | B25: Register unsuccessful by Confirm Password | C25: Stay at Register screen | D25: 1. Fill all required fields 2. Input unmatched confirm password 3. Click Register | E25: 2.1 Verify that system displays error when Confirm Password is empty | F25: First Name: abc Last Name: abc Email: h@gmail.com Password: 123456 Confirm Password: " " | G25: High | H25: Error message displayed: "Password is required." | I25: Passed | J25: Passed
A26: RE-024 | E26: 2.2 Verify that system displays error when Confirm Password does not match Password | F26: First Name: abc Last Name: abc Email: h@gmail.com Password: 123456 Confirm Password: 123 | G26: High | I26: Passed | J26: Passed
A27: RE-025 | B27: Password field masking | C27: Stay at Register screen | D27: 1. Input password | E27: 1.1 Verify that password field masks input characters | F27: First Name: abc Last Name: abc Email: h@gmail.com Password: 123456 Confirm Password: 123456 | G27: Medium | H27: Password shown as ****** | I27: Passed | J27: Passed
A28: RE-026 | B28: Enter key works instead of click Register button | C28: Stay at Register screen | D28: 1. Fill all required fields 2. Press Enter key | E28: 2.1 Verify that user can submit registration form using Enter key | F28: First Name: abc Last Name: abc Email: h@gmail.com Password: 123456 Confirm Password: 123456 | G28: Medium | H28: Registration form is submitted and user is registered successfully | I28: Passed | J28: Passed

Sheet Search Product
A1: TC-ID | B1: Description (Test Scenario) | C1: Pre-condition | D1: Test step | E1: Step condition to perform | F1: Data | G1: Priority | H1: Expected result | I1: Testing Result | K1: Date | L1: Who checked | M1: BUG ID | N1: Comment
I2: Chrome | J2: Microsoft Egde
A3: SR-001 | B3: Search Keyword Validations | C3: Stay at Home page | D3: 1. Input keyword into Search box 2. Click 'Search' button | E3: 1.1 Verify that system displays validation message when user searches with empty keyword | F3: "" | G3: High | H3: Message: "Search term minimum length is 3 characters" No search results displayed | I3: Passed | J3: Passed
A4: SR-002 | E4: 1.2 Verify that system displays validation message when user searches with only spaces | F4: " " | G4: High | H4: Message: "Search term minimum length is 3 characters" No search results displayed | I4: Passed | J4: Passed
A5: SR-003 | E5: 1.3 Verify that system handles search with special characters | F5: "@#$%^" | G5: High | H5: Message: "No products were found" | I5: Passed | J5: Passed
A6: SR-004 | E6: 1.4 Verify that system handles search with very long keyword | F6: 200+ characters | G6: High | H6: Message: "No products were found" | I6: Passed | J6: Passed
A7: SR-005 | E7: 1.5 Verify that user can search with valid keyword (> 3 characters) | F7: "Apple" | G7: High | H7: Results display products containing the keyword. | I7: Passed | J7: Passed
A8: SR-006 | E8: 1.6 Verify that user can search with keyword of exactly 3 characters | F8: "cam" | G8: High | H8: Results display products containing the keyword. | I8: Passed | J8: Passed
A9: SR-007 | E9: 1.7 Verify that system displays validation message when keyword is less than 3 characters | F9: ab | G9: High | H9: Message: "Search term minimum length is 3 characters" | I9: Passed | J9: Passed
A10: SR-008 | E10: 1.8 Verify that system trims leading and trailing spaces in search keyword | F10: " laptop " | G10: Medium | H10: System trims spaces and returns results for "laptop". | I10: Passed | J10: Passed
A11: SR-009 | E11: 1.9 Verify that system displays no results message for non-existing keyword | F11: "xyz123" | G11: Medium | H11: Message: "No products were found that matched your criteria." | I11: Passed | J11: Passed
A12: SR-010 | E12: 1.10 Verify that system performs case-insensitive search | F12: "BUILD" / "build" | G12: Medium | H12: Both searches return the exact same product list | I12: Passed | J12: Passed
A13: SR-011 | B13: Search using Enter key | C13: Stay at Home page | D13: 1. Input keyword 2. Press Enter | E13: 2.1 Verify that user can search using Enter key | F13: laptop | G13: Medium | H13: System performs search | I13: Passed | J13: Passed
A14: SR-012 | B14: Advanced Search UI & Logic | C14: Stay at Search page | D14: 1. Check/Uncheck 'Advanced search' checkbox | E14: 1.1 Verify that Advanced Search options are displayed when checkbox is checked | F14: Checked | G14: High | H14: Advanced options (Category, Manufacturer) become visible. | I14: Passed | J14: Passed
A15: SR-013 | E15: 1.2 Verify that Advanced Search options are hidden when checkbox is unchecked | F15: Unchecked | G15: Medium | H15: Advanced options are hidden. | I15: Passed | J15: Passed
A16: SR-014 | B16: Filter by Category & Manufacturer | C16: Stay at Search page | D16: 1. Input keyword 2. Enable Advanced Search 3. Select filters 4. Click 'Search' | E16: 3.1 Verify that user can filter search results by Category with keyword | F16: Keyword: "Nokia", Category:"Electronics/Cellphones" | G16: High | H16: Only products within "Electronics" and contain keyword are displayed. | I16: Passed | J16: Passed
A17: SR-015 | E17: 3.2 Verify that user can filter search results by Manufacturer with keyword | F17: Keyword: "Cam", Manufacturer: "Apple" | G17: High | H17: Only products made by Apple are displayed. | I17: Passed | J17: Passed
A18: SR-016 | E18: 3.3 Verify that user can filter search results by both Category and Manufacturer | F18: Keyword: "Camera" Category: Electronics Manufacturer: Apple | G18: High | H18: Only products matching keyword "Camera" in "Electronics" category and from "Apple" are displayed | I18: Passed | J18: Passed
A19: SR-017 | E19: 3.4 Verify that user can search with Category including subcategories | F19: Keyword: "Camera", Category: "Electronics", Sub-cat: Checked | G19: High | H19: Displays products in "Camera" and all its sub-folders. | I19: Passed | J19: Passed
A20: SR-018 | E20: 3.5 Verify that user can search with Category filter when keyword is empty | F20: Keyword: "", Category: "Electronics" | G20: High | H20: Message: "Search term minimum length is 3 characters" | I20: Passed | J20: Passed
A21: SR-019 | E21: 3.6 Verify that user can search with Manufacturer filter when keyword is empty | F21: Keyword: "", Manufacturer: "Apple" | G21: High | I21: Passed | J21: Passed
A22: SR-020 | E22: 3.7 Verify that user can search with Category and Manufacturer when keyword is empty | F22: Keyword: "", Category: "Electronics", Manufacturer: "Apple" | G22: High | I22: Passed | J22: Passed
A23: SR-021 | B23: Extended Search Scope | C23: Stay at Search page | D23: 1. Enable Advanced Search 2. Check scope options 3. Click 'Search' | E23: 2.1 Verify that user can search within product descriptions | F23: Keyword: "Cam", Check "Search in product descriptions" | G23: Low | H23: System finds keyword "cam" within the product's long description text. | I23: Passed | J23: Passed
A24: SR-022 | E24: 2.2 Verify that user can search within product tags | F24: Keyword: "Cam", Check "Search in product tags" | G24: Low | H24: System finds products associated with the specific tag. | I24: Passed | J24: Passed
A25: SR-023 | B25: Sort Search Results | C25: Search results are displayed | D25: 1. Click 'Sort by' dropdown 2. Select an option | E25: 1.1 Verify that user can sort results by Name (A to Z) | F25: Option: Name A-Z / Z-A | G25: Medium | H25: Products are sorted alphabetically by title (A to Z / Z to A). | I25: Passed | J25: Passed
A26: SR-024 | E26: 1.2 Verify that user can sort results by Price | F26: Option: Price Low-High / High-Low | G26: Medium | H26: Products are sorted from lowest price to highest price or highest price to lowest price | I26: Passed | J26: Passed
A27: SR-025 | E27: 1.3 Verify that user can sort results by Created on | F27: Option: Created on | G27: Medium | H27: Products are sorted by the date they were added to the system (Newest first). | I27: Passed | J27: Passed

Sheet Product Category
A1: TC-ID | B1: Description (Test Scenario) | C1: Pre-condition | D1: Test step | E1: Step condition to perform | F1: Data | G1: Priority | H1: Expected result | I1: Testing Result | K1: Date | L1: Who checked | M1: BUG ID | N1: Comment
I2: Chrome | J2: Microsoft Egde
A3: PC-001 | B3: Category Basic | C3: Stay at Home page | D3: 1. Click a category on Menu | E3: 1.1 Verify that user can view category page with products | F3: "Computers" | G3: High | H3: Page loads successfully; Title and Breadcrumb match(Home / Computers), Show Sub-Category name. | I3: Passed | J3: Passed
A4: PC-002 | E4: 1.2 Verify that system displays message when category has no products | F4: "" | G4: High | H4: Message: "No products were found" displayed. | I4: Un-test | J4: Un-test
A5: PC-003 | B5: Sub-category | C5: Stay at Home page | D5: 1. Hover over category have sub-category in menu 2. Click on sub-category | E5: 1.1 Verify that sub-categories are displayed on hovering over a category | F5: "Computers" | G5: High | H5: Sub-categories are displayed correctly when user hovers over parent category. | I5: Passed | J5: Passed
A6: PC-004 | E6: 2.1 Verify that user can navigate to sub-category page | F6: Category: "Computers" Sub-category: "Notebooks" | G6: High | H6: Redirection to Notebooks Breadcrumb: Home / Computers / Notebooks Product list is displayed | I6: Passed | J6: Passed
A7: PC-005 | B7: Breadcrumb | C7: User is on Category page | D7: 1. Open Category page 2. Observe breadcrumb 3. Click breadcrumb items | E7: 2.1 Verify that breadcrumb is displayed correctly on category page | F7: Home / Computers | G7: High | H7: Breadcrumb displays correctly (Home / Category) | I7: Passed | J7: Passed
A8: PC-006 | E8: 3.1 Verify that user can navigate to Home page via breadcrumb | F8: Click "Home" | G8: High | H8: User is redirected to Home page | I8: Passed | J8: Passed
A9: PC-007 | C9: User is on Sub-category page | E9: 2.2 Verify that sub-category breadcrumb hierarchy is correct | F9: Computers / Notebooks | G9: High | H9: Breadcrumb shows full (Home / Computers / Notebooks) | I9: Passed | J9: Passed
A10: PC-008 | E10: 3.2 Verify that user can navigate to parent category via breadcrumb | F10: Click "Computers" | G10: High | H10: User is redirected to parent category page | I10: Passed | J10: Passed
A11: PC-009 | B11: View Mode | C11: User is on Product List page | D11: 1. Change View Mode (Grid/List) 2. Perform other actions (Filter/Sort/Page) 3. Navigate away and back | E11: 1.1 Verify default view mode is applied correctly | F11: Open Category | G11: Medium | H11: Default view is displayed; Icon for Grid view is highlighted. | I11: Passed | J11: Passed
A12: PC-010 | E12: 1.2 Verify that products are displayed correctly in Grid view | F12: Click Grid View | G12: Medium | H12: Products are displayed in a responsive grid layout correctly. | I12: Passed | J12: Passed
A13: PC-011 | E13: 1.3 Verify that products are displayed correctly in List view | F13: Click List View | G13: Medium | H13: Layout switches to rows; product details (description) are more visible. | I13: Passed | J13: Passed
A14: PC-012 | E14: 1.4 Verify that user can toggle between Grid and List view | F14: Click Grid View | G14: Low | H14: View mode switches correctly between Grid and List view. | I14: Passed | J14: Passed
A15: PC-013 | E15: 2.5 Verify that selected view mode is maintained after pagination, sorting, and filtering | F15: Select category: Electronics/Cell phones - Select List view -> Go to Page 2 - Select List view -> Apply Sort - Select List view -> Apply Filter | G15: Medium | H15: Selected view mode remains applied after pagination, sorting, and filtering actions. | I15: Passed | J15: Passed
A16: PC-014 | B16: Product Navigation | C16: User is on Product List page | D16: 1. Locate a product 2. Click product (name/image) 3. Observe Product Detail page | E16: 2.1 Verify that user can navigate to product detail page from product list | F16: Category: Computers / Notebooks / Apple MacBook Pro | G16: High | H16: User is redirected to correct Product Detail page | I16: Passed | J16: Passed
A17: PC-015 | B17: Product Action | C17: User is on Product List page | D17: 1. Locate a product 2. Click action | E17: 2.1 Verify that user can add product to cart from product list | F17: Any product | G17: High | H17: Product is added to cart; success notification displayed; cart icon updates quantity | I17: Passed | J17: Passed
A18: PC-016 | E18: 2.2 Verify that system requires selecting options before adding configurable product to cart | F18: Click Category: computers -> Desktops -> "Build your own computer" | G18: High | H18: User is redirected to product detail page or prompted to select required options before adding | I18: Passed | J18: Passed
A19: PC-017 | E19: 2.3 Verify that user can add product to wishlist from product list | F19: Any product | G19: High | H19: Product is added to wishlist; success message displayed | I19: Passed | J19: Passed
A20: PC-018 | E20: 2.4Verify that system requires selecting options before adding configurable product to wishlist | F20: Click Category: computers -> Desktops -> "Build your own computer" | G20: High | H20: User is redirected to product detail page to select required options before adding | I20: Passed | J20: Passed
A21: PC-019 | E21: 2.5 Verify that user can add product to compare list | F21: Any product | G21: High | H21: Product is added to compare list; success notification displayed | I21: Passed | J21: Passed
A22: PC-020 | B22: Filter Logic | C22: User is on Category page | D22: 1. Navigate to a category (ex:Computers / Notebooks) 2. Apply single/multiple filters 3. Observe product list | E22: 1.1 Verify that user can apply a single filter | F22: Filter: "Manufacturer: Apple" | G22: High | H22: Only products matching selected filter are displayed. | I22: Passed | J22: Passed
A23: PC-021 | E23: 2.2 Verify that user can apply multiple filters simultaneously | F23: Filter by attributes: Intel Core i5 Filter by manufacturer: HP | G23: High | H23: Products must match ALL selected filters | I23: Passed | J23: Passed
A24: PC-022 | B24: Pagination Logic | C24: User is on Category page | D24: 1. Navigate to a category (ex:Electronics / Cell phones) 2. Select Display "3" per page 3. Navigate via numbers/buttons pagination | E24: 3.1 Verify that Previous button is disabled on the first page | F24: Page 1 | G24: High | H24: "Previous" button is disabled, Current page = 1, "Next" button is enabled | I24: Passed | J24: Passed
A25: PC-023 | E25: 3.2 Verify that user can navigate to next or specific page | F25: On Page 1 Click "Next" or "Page 2/2" | G25: High | H25: Page 2 products are displayed correctly "Previous" is enabled Current page = "2" | I25: Passed | J25: Passed
A26: PC-024 | E26: 3.3 Verify that Next button is disabled on the last page | F26: Navigate to Last Page | G26: Medium | H26: "Next" button is disabled; "Previous" remains enabled. | I26: Passed | J26: Passed
A27: PC-025 | E27: 3.4 Verify that user can navigate to previous page | F27: Click "Previous" from Page 2 | G27: Medium | H27: User redirected to Page 1; Correct products for Page 1 displayed. | I27: Passed | J27: Passed
A28: PC-026 | B28: Page Size Configuration | C28: User is on Category page | D28: 1. Navigate to a category (ex:Electronics / Cell phones) 2. Select "Display per page" 3. Observe pagination | E28: 2.1 Verify that number of products per page changes based on selected page size | F28: Select 3 / 6 / 9 | G28: Medium | H28: Product count per page updates; Pagination total pages recalculate correctly | I28: Passed | J28: Passed
A29: PC-027 | E29: 1.2 Verify that page resets or updates correctly when changing page size on page greater than 1 | F29: On Page 2 -> Change Page Size( 3 -> 6) | G29: High | H29: System resets to Page 1 | I29: Passed | J29: Passed
A30: PC-028 | B30: URL Pagination | C30: User manually edits URL | D30: 1. Navigate to a category (ex:Electronics / Cell phones) 2. Select Display "3" per page 3. Input invalid values in ?pagenumber= parameter | E30: 3.1 Verify that system handles zero or negative page number correctly | F30: ?pagenumber=0 or ?pagenumber=-1 | G30: High | H30: System defaults to Page 1 and loads valid products | I30: Passed | J30: Passed
A31: PC-029 | E31: 3.2 Verify that system handles page number exceeding total pages | F31: ?pagenumber=999 | G31: High | H31: Error:"No products were found that matched your criteria." | I31: Passed | J31: Passed
A32: PC-030 | E32: 3.3 Verify that system handles non-numeric page number input | F32: ?pagenumber=abc | G32: Medium | H32: System defaults to Page 1 and loads valid products | I32: Passed | J32: Passed

Sheet Add Review
A1: TC-ID | B1: Description (Test Scenario) | C1: Pre-condition | D1: Test step | E1: Step condition to perform | F1: Data | G1: Priority | H1: Expected result | I1: Testing Result | K1: Date | L1: Who checked | M1: BUG ID | N1: Comment
I2: Chrome | J2: Microsoft Egde
A3: RV-001 | B3: View reviews without login | C3: Stay at Product page, User not logged in | D3: 1. Navigate to a category (ex:Category: Computers /Notebooks /Apple MacBook Pro ) 2. Scroll to Review section | E3: 1.1 Verify that user can view product reviews without login | G3: High | H3: Reviews displayed, Add Review button disabled, cannot vote | I3: Passed | J3: Passed
A4: RV-002 | B4: Add review with valid data | C4: User logged in, on Product List page | D4: 1. Navigate to a category (ex:Category: Computers /Notebooks /Apple MacBook Pro ) 2. Click Add Your Review 3. Enter valid title and text 4. Select rating 5. Click Submit | E4: 5.1 Verify that user can submit a review with valid data | F4: Title: "Excellent Camera" Text: "Great image quality and easy to use" Rating: 5 | G4: High | H4: Review submitted successfully, appears in review list | I4: Passed | J4: Passed
A5: RV-003 | B5: Add Review Title | C5: User logged in | D5: 1. Navigate to a category (ex:Category: Computers /Notebooks /Apple MacBook Pro ) 2. Click Add Your Review 3. Enter title 4. Enter valid text 5. Select rating 6. Submit | E5: 3.1 Verify that system shows error when review title is empty | F5: Title: "" Text: "Good camera" Rating: 4 | G5: High | H5: Error: "Review title is required" | I5: Passed | J5: Passed
A6: RV-004 | E6: 3.2 Verify that user can submit review title containing special characters | F6: Title: "@#$%^&*" Text: "Good camera" Rating: 4 | G6: Medium | H6: Review submitted successfully. | I6: Passed | J6: Passed
A7: RV-005 | E7: 3.3 Verify that system shows error when review title exceeds maximum length | F7: Title: 201 chars Text: "Good camera" Rating: 4 | G7: Medium | H7: Error: "Max length of product review title is 200 chars" | I7: Passed | J7: Passed
A8: RV-006 | E8: 3.4 Verify that system accepts review title at minimum boundary value | F8: Title: 1 char Text: "Good camera" Rating: 5 | G8: Medium | H8: Review submitted successfully | I8: Passed | J8: Passed
A9: RV-007 | E9: 3.5 Verify that system accepts review title at maximum boundary value | F9: Title: 200 chars Text: "Good camera" Rating: 5 | G9: Medium | H9: Review submitted successfully | I9: Passed | J9: Passed
A10: RV-008 | B10: Add Review Text | C10: User logged in | D10: 1. Navigate to a category (ex:Category: Computers /Notebooks /Apple MacBook Pro ) 2. Click Add Your Review 3. Enter valid title 4. Enter text 5. Select rating 6. Submit | E10: 4.1 Verify that system shows error when review text is empty | F10: Title: "Nice camera" Text: "" Rating: 4 | G10: High | H10: Error: "Review text is required" | I10: Passed | J10: Passed
A11: RV-009 | E11: 4.2 Verify that user can submit review text containing special characters | F11: Title: "Nice camera" Text: "@#$%^&*" Rating: 4 | G11: Medium | H11: Review submitted successfully. | I11: Passed | J11: Passed
A12: RV-010 | E12: 4.3 Verify that system accepts review text at minimum boundary value | F12: Title: "Good camera" Text: a Rating: 5 | G12: Medium | H12: Review submitted successfully | I12: Passed | J12: Passed
A13: RV-011 | B13: Add Review Rating | C13: User logged in | D13: 1. Navigate to a category (ex:Category: Computers /Notebooks /Apple MacBook Pro ) 2. Click Add Your Review 3. Enter valid title & text 4. Select rating 5. Submit | E13: 4.1 Verify that default rating is applied when no rating is selected | F13: Title: "Good camera" Text: "Works well" Rating: not choose | G13: Medium | H13: Review submitted with default 5 stars | I13: Passed | J13: Passed
A14: RV-012 | E14: 4.2 Verify that user can select rating from 1 to 5 stars | F14: Rating: 1,2,3,4,5 | G14: Medium | H14: Review submitted successfully | I14: Passed | J14: Passed
A15: RV-013 | B15: Helpfulness vote | C15: User logged in | D15: 1. Navigate to a category (ex:Category: Computers /Notebooks /Apple MacBook Pro ) 2. Scroll to review 3. Click Yes/No for helpfulness | E15: 3.1 Verify that user cannot vote helpfulness without login | G15: Medium | H15: Vote not allowed | I15: Passed | J15: Passed
A16: RV-014 | E16: 3.2 Verify that user cannot vote on their own review | G16: Medium | H16: System prevents voting own review | I16: Passed | J16: Passed
A17: RV-015 | E17: 3.3 Verify that user can vote other users’ reviews as helpful or not helpful | G17: Medium | H17: Helpfulness count increases by 1 | I17: Passed | J17: Passed

Sheet Shopping Cart
A1: TC-ID | B1: Description (Test Scenario) | C1: Pre-condition | D1: Test steps | E1: Step condition to perform | F1: Data | G1: Priority | H1: Expected result | I1: Testing Result | K1: Date | L1: Who checked | M1: BUG ID | N1: Comment
I2: Chrome | J2: Microsoft Egde
A3: SC-001 | B3: Add Simple product to Cart | C3: User is on Product List page | D3: 1. Select a product want to add 2. Click "Add to Cart" button 3. Check Cart/Mini-cart | E3: 1.1 Verify that user can add simple product to cart( not Required Options) | F3: Category: Books Product: First Prize Pies | G3: High | H3: Product added successfully; Success message appears; Cart counter increases. | I3: Passed | J3: Passed
A4: SC-002 | E4: 1.2 Verify that system handles adding duplicate product to cart | F4: Category: Books Product: First Prize Pies (Twice) | G4: Medium | H4: Product is NOT duplicated as a new row; Quantity increases in the cart. | I4: Passed | J4: Passed
A5: SC-003 | B5: Add Configurable Product | C5: User is on Product Detail page | D5: 1. Select a product want to add( Computers / Desktops / Build your own computer) 2. Open configurable product detail page 3. Select required configuration options 4. Click "Add to Cart" 5. Check Cart/Mini-car | E5: 1.1 Verify that system requires selecting product options before adding to cart | F5: Category: Computers / Desktops / Build your own computer" (Required RAM/HDD) | G5: High | H5: If clicked from Category: Redirect to Detail page. If on Detail: Highlight validation error for missing options. ( Please select RAM Please select HDD) | I5: Passed | J5: Passed
A6: SC-004 | E6: 3.1 Verify that user can add configurable product with required options | F6: Category: Computers / Desktops / Build your own computer RAM: 8GB HDD: 320GB | G6: High | H6: Product added successfully; Product displayed correctly in cart with selected configuration | I6: Passed | J6: Passed
A7: SC-005 | E7: 3.2 Verify that product price updates after selecting configurable options | F7: Category: Computers / Desktops / Build your own computer RAM: 8GB HDD: 400GB | G7: High | H7: Product price updates dynamically according to selected configuration options | I7: Passed | J7: Passed
A8: SC-006 | E8: 5.1 Verify that selected configuration is displayed correctly in shopping cart | G8: High | H8: Shopping cart displays correct selected configuration information including RAM and HDD options | I8: Passed | J8: Passed
A9: SC-007 | E9: 5.2 Verify that different configurations create separate cart rows | F9: "Category: Computers / Desktops / Build your own computer Config A: RAM 8GB + HDD 320GB Config B: RAM 16GB + HDD 400GB | G9: High | H9: Shopping cart displays configurable products as separate rows | I9: Passed | J9: Passed
A10: SC-008 | B10: Quantity Boundary Validation | C10: User is on Product List page | D10: 1. Select a product( Category: Computers / Notebookst / Asus Laptop) 2. Click product detail page 3. Input Quantity( Max: 10.000) 4. Click "Add to Cart" button 5. Check Cart/Mini-cart | E10: 3.1 Verify that system accepts minimum quantity | F10: Qty = 1 | G10: High | H10: Product is added to cart successfully. | I10: Passed | J10: Passed
A11: SC-009 | E11: 3.2 Verify that system accepts near lower boundary quantity | F11: Qty = 2 | G11: Medium | H11: Product is added to cart successfully. | I11: Passed | J11: Passed
A12: SC-010 | E12: 3.3 Verify that system accepts valid mid-range quantity | F12: Qty = 5000 | G12: High | H12: Product is added to cart successfully. | I12: Passed | J12: Passed
A13: SC-011 | E13: 3.4 Verify that system accepts near upper boundary quantity | F13: Qty = 9999 | G13: High | H13: Product is added to cart successfully. | I13: Passed | J13: Passed
A14: SC-012 | E14: 3.5 Verify that system accepts maximum quantity | F14: Qty = 10000 | G14: High | H14: Product is added to cart successfully. | I14: Passed | J14: Passed
A15: SC-013 | E15: 3.6 Verify that system shows error when quantity exceeds maximum limit | F15: Qty = 10001 | G15: High | H15: Error message: "The maximum quantity allowed for purchase is 10000." | I15: Passed | J15: Passed
A16: SC-014 | E16: 3.7 Verify that system shows error when out-of-range quantity | F16: Qty = 0 | G16: High | H16: Error message: "Quantity should be positive." | I16: Passed | J16: Passed
A17: SC-015 | E17: 3.8 Verify that system shows error when negative quantity | F17: Qty = -5 | G17: High | H17: Error message: "Quantity should be positive." | I17: Passed | J17: Passed
A18: SC-016 | E18: 3.9 Verify that system rejects shows error when decimal quantity | F18: Qty = 10.5 | G18: Medium | H18: Error message: "Quantity should be positive." | I18: Passed | J18: Passed
A19: SC-017 | E19: 3.10 Verify that system shows error when non-numeric input | F19: Qty = "abc" | G19: High | H19: Error message: "Quantity should be positive." | I19: Passed | J19: Passed
A20: SC-018 | E20: 3.11 Verify that system shows error when empty quantity input | F20: Qty = " " | G20: Medium | H20: Error message: "Quantity should be positive." | I20: Passed | J20: Passed
A21: SC-019 | E21: 3.12 Verify that system enforces total cart quantity limit | F21: 1st Add: 6.000 2nd Add: 5.000 | G21: Medium | H21: The 2nd fails. Error: "The maximum quantity allowed for purchase is 10000." | I21: Passed | J21: Passed
A22: SC-020 | B22: Rental Date Validation | C22: User is on Product Detail page | D22: 1. Select a product( Category: Jewelry /Elegant Gemstone Necklace (rental)) 2. Click product detail page 3. Select Start Date / End Date. 4. Click "Rent". | E22: 3.1 Verify that user can select valid rental date range | F22: Start < End (ex: Start: Today, End: Tomorrow) | G22: High | H22: System accepts dates; Product is added to cart; Rental days calculated correctly. | I22: Passed | J22: Passed
A23: SC-021 | E23: 3.2 Verify that system enforces minimum rental duration | F23: Start = End | G23: Medium | H23: System accepts;The rental fee is calculated 1 day. | I23: Passed | J23: Passed
A24: SC-022 | E24: 3.3Verify that system rejects invalid date range | F24: Start > End | G24: High | H24: Error: "Rental start date should be less than end date" | I24: Passed | J24: Passed
A25: SC-023 | E25: 3.4 Verify that system rejects past dates | F25: Start < Today | G25: High | H25: Error: "Rental start date should be the future date" | I25: Passed | J25: Passed
A26: SC-024 | E26: 3.5 Verify that system requires start and end dates | F26: Start= " ", Today= " " | G26: High | H26: Error: "Enter rental start date" | I26: Passed | J26: Passed
A27: SC-025 | E27: 3.6 Verify that system rejects invalid date format | F27: mm/dd/yyyy instead of dd/mm/yyyy | G27: Medium | H27: Error: "Enter rental start date" | I27: Passed | J27: Passed
A28: SC-026 | E28: 3.7 Verify that system rejects non-numeric date input | F28: Start= " abc", Today= "abc " | G28: High | H28: System prevents typing non-numeric characters | I28: Passed | J28: Passed
A29: SC-027 | B29: Donation Price Validation | C29: User is on Detail page | D29: 1. Select a product( Category: Digital downloads / If You Wait (donation)) 2. Click product detail page 3. Enter your price. 4. Click "Add to Cart". | E29: 3.1 Verify that system accepts minimum valid donation price | F29: Price: $0.50 | G29: High | H29: System accepts; Product added to cart with price $0.50. | I29: Passed | J29: Passed
A30: SC-028 | E30: 3.2 Verify that system accepts valid above minimum price | F30: Price: $0.51 | G30: Medium | H30: System accepts; Product added to cart with price $0.51. | I30: Passed | J30: Passed
A31: SC-029 | E31: 3.3 Verify that system rejects below minimum price | F31: Price: $0.49 | G31: High | H31: Error: "The price must be from $0.50 to $100.00." | I31: Passed | J31: Passed
A32: SC-030 | E32: 3.4 Verify that system accepts valid mid-range price | F32: Price: $50.00 | G32: High | H32: System accepts; Product added to cart with price $50.00. | I32: Passed | J32: Passed
A33: SC-031 | E33: 3.5 Verify that system accepts maximum valid price | F33: Price: $100.00 | G33: High | H33: System accepts; Product added to cart with price $100.00. | I33: Passed | J33: Passed
A34: SC-032 | E34: 3.6 Verify that system accepts below maximum valid price | F34: Price: $99.99 | G34: Medium | H34: System accepts; Product added to cart with price $99.99. | I34: Passed | J34: Passed
A35: SC-033 | E35: 3.7 Verify that system rejects price exceeding maximum limit | F35: Price: $101.00 | G35: High | H35: Error: "The price must be from $0.50 to $100.00." | I35: Passed | J35: Passed
A36: SC-034 | E36: 3.8 Verify that system rejects non-numeric input | F36: Price: "abc" | G36: High | H36: Error: "The price must be from $0.50 to $100.00." | I36: Passed | J36: Passed
A37: SC-035 | E37: 3.9 Verify that system rejects empty input | F37: Price: " " | G37: High | H37: Error: "The price must be from $0.50 to $100.00." | I37: Passed | J37: Passed
A38: SC-036 | B38: Shopping Cart Quantity Management | C38: Product already added to cart | D38: 1. Open Shopping Cart page 2. Change quantity 3. Click outside quantity field 4. Check Cart/Mini-cart | E38: 2.1 Verify that user can update shopping cart quantity successfully | F38: Product: First Prize Pies Old Qty: 1 New Qty: 3 | G38: High | H38: Quantity updated successfully; Shopping cart quantity displays correctly | I38: Passed | J38: Passed
A39: SC-037 | E39: 4.1 Verify that subtotal and total price are recalculated correctly after quantity update | F39: Product: First Prize Pies Old Qty: 1 New Qty: 5 | G39: High | H39: Product subtotal and total cart price recalculated correctly according to updated quantity | I39: Passed | J39: Passed
A40: SC-038 | B40: Shopping Cart Item Removal | C40: Product already added to cart | D40: 1. Open Shopping Cart page 2. Select Remove checkbox for product 3. Check Cart/Mini-cart | E40: 2.1 Verify that user can remove product from shopping cart successfully | F40: Product: First Prize Pies | G40: High | H40: Selected product removed successfully from shopping cart; Cart quantity updated correctly | I40: Passed | J40: Passed
...

Sheet Summary
A1: Name | B1: Total | C1: Chrome | F1: Microsoft Edge
C2: Passed | D2: Failed | E2: Un-test | F2: Passed | G2: Failed | H2: Un-test
A3: Register | B3: =COUNTIF(Register!A3:A40,"RE*") -> 26 | C3: =COUNTIF(Register!I3:I40,"passed*") -> 18 | D3: =COUNTIF(Register!I3:I40,"failed*") -> 8 | E3: =COUNTIF(Register!I3:I40,"un-test*") -> 0 | F3: =COUNTIF(Register!J3:J40,"passed*") -> 18 | G3: =COUNTIF(Register!J3:J40,"failed*") -> 8 | H3: =COUNTIF(Register!J3:J40,"un-test*") -> 0
A4: Search Product | B4: =COUNTIF('Search Product'!A3:A32,"SR*") -> 25 | C4: =COUNTIF('Search Product'!I3:I32,"Passed*") -> 25 | D4: =COUNTIF('Search Product'!I3:I32,"failed*") -> 0 | E4: =COUNTIF('Search Product'!I3:I32,"Un-test*") -> 0 | F4: =COUNTIF('Search Product'!J3:J32,"Passed*") -> 25 | G4: =COUNTIF('Search Product'!J3:J32,"Failed*") -> 0 | H4: =COUNTIF('Search Product'!J3:J32,"Un-test*") -> 0
A5: Product Category | B5: =COUNTIF('Product Category'!A3:A40,"PC*") -> 30 | C5: =COUNTIF('Product Category'!I3:I40,"Passed*") -> 29 | D5: =COUNTIF('Product Category'!I3:I40,"failed*") -> 0 | E5: =COUNTIF('Product Category'!I3:I40,"Un-test*") -> 1 | F5: =COUNTIF('Product Category'!J3:J40,"Passed*") -> 29 | G5: =COUNTIF('Product Category'!J3:J40,"Failed*") -> 0 | H5: =COUNTIF('Product Category'!J3:J40,"Un-test*") -> 1
A6: Add Review | B6: =COUNTIF('Add Review'!A3:A20,"RV*") -> 15 | C6: =COUNTIF('Add Review'!I3:I20,"Passed*") -> 15 | D6: =COUNTIF('Add Review'!I3:I40,"failed*") -> 0 | E6: =COUNTIF('Add Review'!I3:I24,"Un-test*") -> 0 | F6: =COUNTIF('Add Review'!J3:J20,"Passed*") -> 15 | G6: =COUNTIF('Add Review'!J3:J20,"Failed*") -> 0 | H6: =COUNTIF('Add Review'!J3:J20,"Un-test*") -> 0
A7: Shopping Cart | B7: =COUNTIF('Shopping Cart'!A3:A49,"SC*") -> 43 | C7: =COUNTIF('Shopping Cart'!I3:I49,"Passed*") -> 43 | D7: =COUNTIF('Shopping Cart'!I3:I49,"failed*") -> 0 | E7: =COUNTIF('Shopping Cart'!I3:I49,"Un-test*") -> 0 | F7: =COUNTIF('Shopping Cart'!J3:J49,"Passed*") -> 43 | G7: =COUNTIF('Shopping Cart'!J3:J49,"Failed*") -> 0 | H7: =COUNTIF('Shopping Cart'!J3:J49,"Un-test*") -> 0
B8: =SUM(B3:B7) -> 139
